[2022-05-13 15:28:19,565] {taskinstance.py:876} INFO - Dependencies all met for <TaskInstance: my_dag_v0.0.1.my_task_3 2022-05-05T00:00:00+00:00 [queued]>
[2022-05-13 15:28:19,581] {taskinstance.py:876} INFO - Dependencies all met for <TaskInstance: my_dag_v0.0.1.my_task_3 2022-05-05T00:00:00+00:00 [queued]>
[2022-05-13 15:28:19,581] {taskinstance.py:1067} INFO - 
--------------------------------------------------------------------------------
[2022-05-13 15:28:19,581] {taskinstance.py:1068} INFO - Starting attempt 1 of 1
[2022-05-13 15:28:19,582] {taskinstance.py:1069} INFO - 
--------------------------------------------------------------------------------
[2022-05-13 15:28:19,587] {taskinstance.py:1087} INFO - Executing <Task(PythonOperator): my_task_3> on 2022-05-05T00:00:00+00:00
[2022-05-13 15:28:19,591] {standard_task_runner.py:52} INFO - Started process 400 to run task
[2022-05-13 15:28:19,593] {standard_task_runner.py:76} INFO - Running: ['airflow', 'tasks', 'run', 'my_dag_v0.0.1', 'my_task_3', '2022-05-05T00:00:00+00:00', '--job-id', '36', '--pool', 'default_pool', '--raw', '--subdir', 'DAGS_FOLDER/my_dag_v_0_1_0_0.py', '--cfg-path', '/tmp/tmpukn5aoau', '--error-file', '/tmp/tmpuu47f8x_']
[2022-05-13 15:28:19,595] {standard_task_runner.py:77} INFO - Job 36: Subtask my_task_3
[2022-05-13 15:28:19,621] {logging_mixin.py:104} INFO - Running <TaskInstance: my_dag_v0.0.1.my_task_3 2022-05-05T00:00:00+00:00 [running]> on host bacb497a28fb
[2022-05-13 15:28:19,658] {taskinstance.py:1282} INFO - Exporting the following env vars:
AIRFLOW_CTX_DAG_EMAIL=msbeni@gmail.com
AIRFLOW_CTX_DAG_OWNER=msbeni
AIRFLOW_CTX_DAG_ID=my_dag_v0.0.1
AIRFLOW_CTX_TASK_ID=my_task_3
AIRFLOW_CTX_EXECUTION_DATE=2022-05-05T00:00:00+00:00
AIRFLOW_CTX_DAG_RUN_ID=scheduled__2022-05-05T00:00:00+00:00
[2022-05-13 15:28:19,658] {taskinstance.py:1481} ERROR - Task failed with exception
Traceback (most recent call last):
  File "/home/airflow/.local/lib/python3.6/site-packages/airflow/models/taskinstance.py", line 1137, in _run_raw_task
    self._prepare_and_execute_task_with_callbacks(context, task)
  File "/home/airflow/.local/lib/python3.6/site-packages/airflow/models/taskinstance.py", line 1311, in _prepare_and_execute_task_with_callbacks
    result = self._execute_task(context, task_copy)
  File "/home/airflow/.local/lib/python3.6/site-packages/airflow/models/taskinstance.py", line 1341, in _execute_task
    result = task_copy.execute(context=context)
  File "/home/airflow/.local/lib/python3.6/site-packages/airflow/operators/python.py", line 150, in execute
    return_value = self.execute_callable()
  File "/home/airflow/.local/lib/python3.6/site-packages/airflow/operators/python.py", line 161, in execute_callable
    return self.python_callable(*self.op_args, **self.op_kwargs)
  File "/opt/airflow/dags/my_dag_v_0_1_0_0.py", line 18, in _my_func
    raise ValueError("Error")
ValueError: Error
[2022-05-13 15:28:19,659] {taskinstance.py:1531} INFO - Marking task as FAILED. dag_id=my_dag_v0.0.1, task_id=my_task_3, execution_date=20220505T000000, start_date=20220513T152819, end_date=20220513T152819
[2022-05-13 15:28:19,685] {local_task_job.py:151} INFO - Task exited with return code 1
