[2022-05-12 20:42:26,981] {taskinstance.py:876} INFO - Dependencies all met for <TaskInstance: my_dag.my_task 2022-05-11T00:00:00+00:00 [queued]>
[2022-05-12 20:42:26,990] {taskinstance.py:876} INFO - Dependencies all met for <TaskInstance: my_dag.my_task 2022-05-11T00:00:00+00:00 [queued]>
[2022-05-12 20:42:26,990] {taskinstance.py:1067} INFO - 
--------------------------------------------------------------------------------
[2022-05-12 20:42:26,990] {taskinstance.py:1068} INFO - Starting attempt 1 of 1
[2022-05-12 20:42:26,991] {taskinstance.py:1069} INFO - 
--------------------------------------------------------------------------------
[2022-05-12 20:42:26,999] {taskinstance.py:1087} INFO - Executing <Task(PythonOperator): my_task> on 2022-05-11T00:00:00+00:00
[2022-05-12 20:42:27,004] {standard_task_runner.py:52} INFO - Started process 801 to run task
[2022-05-12 20:42:27,006] {standard_task_runner.py:76} INFO - Running: ['airflow', 'tasks', 'run', 'my_dag', 'my_task', '2022-05-11T00:00:00+00:00', '--job-id', '8', '--pool', 'default_pool', '--raw', '--subdir', 'DAGS_FOLDER/my_dag.py', '--cfg-path', '/tmp/tmpgp14_nmr', '--error-file', '/tmp/tmp1bz444aa']
[2022-05-12 20:42:27,007] {standard_task_runner.py:77} INFO - Job 8: Subtask my_task
[2022-05-12 20:42:27,033] {logging_mixin.py:104} INFO - Running <TaskInstance: my_dag.my_task 2022-05-11T00:00:00+00:00 [running]> on host 7b5fcf14949b
[2022-05-12 20:42:27,071] {taskinstance.py:1282} INFO - Exporting the following env vars:
AIRFLOW_CTX_DAG_OWNER=airflow
AIRFLOW_CTX_DAG_ID=my_dag
AIRFLOW_CTX_TASK_ID=my_task
AIRFLOW_CTX_EXECUTION_DATE=2022-05-11T00:00:00+00:00
AIRFLOW_CTX_DAG_RUN_ID=scheduled__2022-05-11T00:00:00+00:00
[2022-05-12 20:42:27,071] {taskinstance.py:1481} ERROR - Task failed with exception
Traceback (most recent call last):
  File "/home/airflow/.local/lib/python3.6/site-packages/airflow/models/taskinstance.py", line 1137, in _run_raw_task
    self._prepare_and_execute_task_with_callbacks(context, task)
  File "/home/airflow/.local/lib/python3.6/site-packages/airflow/models/taskinstance.py", line 1311, in _prepare_and_execute_task_with_callbacks
    result = self._execute_task(context, task_copy)
  File "/home/airflow/.local/lib/python3.6/site-packages/airflow/models/taskinstance.py", line 1341, in _execute_task
    result = task_copy.execute(context=context)
  File "/home/airflow/.local/lib/python3.6/site-packages/airflow/operators/python.py", line 150, in execute
    return_value = self.execute_callable()
  File "/home/airflow/.local/lib/python3.6/site-packages/airflow/operators/python.py", line 161, in execute_callable
    return self.python_callable(*self.op_args, **self.op_kwargs)
  File "/opt/airflow/dags/my_dag.py", line 13, in _my_func
    print(**kwargs)
TypeError: print() takes at most 4 arguments (33 given)
[2022-05-12 20:42:27,072] {taskinstance.py:1531} INFO - Marking task as FAILED. dag_id=my_dag, task_id=my_task, execution_date=20220511T000000, start_date=20220512T204226, end_date=20220512T204227
[2022-05-12 20:42:27,097] {local_task_job.py:151} INFO - Task exited with return code 1
